[2025-06-17T06:46:54.926+0000] {taskinstance.py:1171} INFO - Dependencies all met for <TaskInstance: Final_Project.load_to_postgre manual__2025-06-17T06:46:42.638979+00:00 [queued]>
[2025-06-17T06:46:54.942+0000] {taskinstance.py:1171} INFO - Dependencies all met for <TaskInstance: Final_Project.load_to_postgre manual__2025-06-17T06:46:42.638979+00:00 [queued]>
[2025-06-17T06:46:54.943+0000] {taskinstance.py:1368} INFO - 
--------------------------------------------------------------------------------
[2025-06-17T06:46:54.944+0000] {taskinstance.py:1369} INFO - Starting attempt 1 of 1
[2025-06-17T06:46:54.945+0000] {taskinstance.py:1370} INFO - 
--------------------------------------------------------------------------------
[2025-06-17T06:46:54.967+0000] {taskinstance.py:1389} INFO - Executing <Task(_PythonDecoratedOperator): load_to_postgre> on 2025-06-17 06:46:42.638979+00:00
[2025-06-17T06:46:54.977+0000] {standard_task_runner.py:52} INFO - Started process 1008 to run task
[2025-06-17T06:46:54.984+0000] {standard_task_runner.py:79} INFO - Running: ['***', 'tasks', 'run', 'Final_Project', 'load_to_postgre', 'manual__2025-06-17T06:46:42.638979+00:00', '--job-id', '12', '--raw', '--subdir', 'DAGS_FOLDER/iphone_etl.py', '--cfg-path', '/tmp/tmpl1zm6c1m', '--error-file', '/tmp/tmpbtpx2xnc']
[2025-06-17T06:46:54.986+0000] {standard_task_runner.py:80} INFO - Job 12: Subtask load_to_postgre
[2025-06-17T06:46:55.628+0000] {task_command.py:371} INFO - Running <TaskInstance: Final_Project.load_to_postgre manual__2025-06-17T06:46:42.638979+00:00 [running]> on host 240725df7103
[2025-06-17T06:46:56.072+0000] {taskinstance.py:1583} INFO - Exporting the following env vars:
AIRFLOW_CTX_DAG_OWNER=Dwi
AIRFLOW_CTX_DAG_ID=Final_Project
AIRFLOW_CTX_TASK_ID=load_to_postgre
AIRFLOW_CTX_EXECUTION_DATE=2025-06-17T06:46:42.638979+00:00
AIRFLOW_CTX_TRY_NUMBER=1
AIRFLOW_CTX_DAG_RUN_ID=manual__2025-06-17T06:46:42.638979+00:00
[2025-06-17T06:46:56.081+0000] {taskinstance.py:1902} ERROR - Task failed with exception
Traceback (most recent call last):
  File "/home/airflow/.local/lib/python3.7/site-packages/airflow/decorators/base.py", line 179, in execute
    return_value = super().execute(context)
  File "/home/airflow/.local/lib/python3.7/site-packages/airflow/operators/python.py", line 171, in execute
    return_value = self.execute_callable()
  File "/home/airflow/.local/lib/python3.7/site-packages/airflow/operators/python.py", line 189, in execute_callable
    return self.python_callable(*self.op_args, **self.op_kwargs)
  File "/opt/airflow/dags/iphone_etl.py", line 130, in load_to_postgre
    port="5434"
  File "/home/airflow/.local/lib/python3.7/site-packages/psycopg2/__init__.py", line 122, in connect
    conn = _connect(dsn, connection_factory=connection_factory, **kwasync)
psycopg2.OperationalError: connection to server at "localhost" (::1), port 5434 failed: Connection refused
	Is the server running on that host and accepting TCP/IP connections?
connection to server at "localhost" (127.0.0.1), port 5434 failed: Connection refused
	Is the server running on that host and accepting TCP/IP connections?

[2025-06-17T06:46:56.235+0000] {taskinstance.py:1412} INFO - Marking task as FAILED. dag_id=Final_Project, task_id=load_to_postgre, execution_date=20250617T064642, start_date=20250617T064654, end_date=20250617T064656
[2025-06-17T06:46:56.273+0000] {standard_task_runner.py:97} ERROR - Failed to execute job 12 for task load_to_postgre (connection to server at "localhost" (::1), port 5434 failed: Connection refused
	Is the server running on that host and accepting TCP/IP connections?
connection to server at "localhost" (127.0.0.1), port 5434 failed: Connection refused
	Is the server running on that host and accepting TCP/IP connections?
; 1008)
[2025-06-17T06:46:56.320+0000] {local_task_job.py:156} INFO - Task exited with return code 1
[2025-06-17T06:46:56.637+0000] {local_task_job.py:279} INFO - 0 downstream tasks scheduled from follow-on schedule check
